Workbook

Sheet Configuración
A1: Parámetro | B1: Valor
A2: Días laborables/mes | B2: 30
A3: Horas/día | B3: 24
A4: IVA % | B4: 21
A5: Margen % | B5: 15

Sheet LLMs
A1: Modelo | B1: Proveedor | C1: €/1M Entrada | D1: €/1M Salida
A2: GPT-5 mini | B2: OpenAI | C2: 0.25 | D2: 2
A3: GPT-5 | B3: OpenAI | C3: 1.25 | D3: 10
A4: Claude Sonnet 4 | B4: Anthropic | C4: 3 | D4: 15
A5: Gemini 2.5 Flash | B5: Google | C5: 0.3 | D5: 2.5
A6: Gemini 2.5 Pro | B6: Google | C6: 1.5 | D6: 10
A7: Mistral Large | B7: Mistral | C7: 2 | D7: 6
A8: GPT-4.1 | B8: OpenAI | C8: 2 | D8: 8
A9: Grok 4 | B9: xAI | C9: 0.59 | D9: 0.79

Sheet Agentes (2)
A1: Agente | B1: LLM | C1: Consultas/día | D1: Días/mes | E1: Consultas/mes | F1: Consultas/año | G1: Input tok/consulta | H1: Output tok/consulta | I1: Input tok/mes | J1: Output tok/mes | K1: €/Entrada | L1: €/Salida | M1: Coste Entrada | N1: Coste Salida | O1: TOTAL Mes | P1: TOTAL Año
A2: Garum (Gestor Correos) | B2: Grok 4 | C2: 25 | D2: =[1]Configuración!$B$2 -> 22 | E2: =C2*D2 -> 550 | F2: =E2*12 -> 6600 | G2: 1200 | H2: 500 | I2: =G2*E2 -> 660000 | J2: =H2*E2 -> 275000 | K2: =INDEX([1]LLMs!$C$2:$C$9,MATCH(B2,[1]LLMs!$A$2:$A$9,0)) -> 1 | L2: =INDEX([1]LLMs!$D$2:$D$9,MATCH(B2,[1]LLMs!$A$2:$A$9,0)) -> 3 | M2: =I2/1000000*K2 -> 0.66 | N2: =J2/1000000*L2 -> 0.825 | O2: =M2+N2 -> 1.485 | P2: =O2*12 -> 17.82
A3: Hermes (Telegram) | B3: Grok 4 | C3: 150 | D3: =[1]Configuración!$B$2 -> 22 | E3: =C3*D3 -> 3300 | F3: =E3*12 -> 39600 | G3: 900 | H3: 450 | I3: =G3*E3 -> 2970000 | J3: =H3*E3 -> 1485000 | K3: =INDEX([1]LLMs!$C$2:$C$9,MATCH(B3,[1]LLMs!$A$2:$A$9,0)) -> 1 | L3: =INDEX([1]LLMs!$D$2:$D$9,MATCH(B3,[1]LLMs!$A$2:$A$9,0)) -> 3 | M3: =I3/1000000*K3 -> 2.97 | N3: =J3/1000000*L3 -> 4.455 | O3: =M3+N3 -> 7.425 | P3: =O3*12 -> 89.1
A4: Lumen (consultas) | B4: Grok 4 | C4: 150 | D4: =[1]Configuración!$B$2 -> 22 | E4: =C4*D4 -> 3300 | F4: =E4*12 -> 39600 | G4: 2500 | H4: 900 | I4: =G4*E4 -> 8250000 | J4: =H4*E4 -> 2970000 | K4: =INDEX([1]LLMs!$C$2:$C$9,MATCH(B4,[1]LLMs!$A$2:$A$9,0)) -> 1 | L4: =INDEX([1]LLMs!$D$2:$D$9,MATCH(B4,[1]LLMs!$A$2:$A$9,0)) -> 3 | M4: =I4/1000000*K4 -> 8.25 | N4: =J4/1000000*L4 -> 8.91 | O4: =M4+N4 -> 17.16 | P4: =O4*12 -> 205.92
A5: Operis (autorellenado) | B5: Grok 4 | C5: 10 | D5: =[1]Configuración!$B$2 -> 22 | E5: =C5*D5 -> 220 | F5: =E5*12 -> 2640 | G5: 1100 | H5: 400 | I5: =G5*E5 -> 242000 | J5: =H5*E5 -> 88000 | K5: =INDEX([1]LLMs!$C$2:$C$9,MATCH(B5,[1]LLMs!$A$2:$A$9,0)) -> 1 | L5: =INDEX([1]LLMs!$D$2:$D$9,MATCH(B5,[1]LLMs!$A$2:$A$9,0)) -> 3 | M5: =I5/1000000*K5 -> 0.242 | N5: =J5/1000000*L5 -> 0.264 | O5: =M5+N5 -> 0.506 | P5: =O5*12 -> 6.072
A6: Vigil (concursos) | B6: Grok 4 | C6: 2 | D6: =[1]Configuración!$B$2 -> 22 | E6: =C6*D6 -> 44 | F6: =E6*12 -> 528 | G6: 1000 | H6: 300 | I6: =G6*E6 -> 44000 | J6: =H6*E6 -> 13200 | K6: =INDEX([1]LLMs!$C$2:$C$9,MATCH(B6,[1]LLMs!$A$2:$A$9,0)) -> 1 | L6: =INDEX([1]LLMs!$D$2:$D$9,MATCH(B6,[1]LLMs!$A$2:$A$9,0)) -> 3 | M6: =I6/1000000*K6 -> 0.044 | N6: =J6/1000000*L6 -> 0.0396 | O6: =M6+N6 -> 0.0836 | P6: =O6*12 -> 1.0032
A7: Jano (viajes) | B7: Grok 4 | C7: 30 | D7: =[1]Configuración!$B$2 -> 22 | E7: =C7*D7 -> 660 | F7: =E7*12 -> 7920 | G7: 1800 | H7: 700 | I7: =G7*E7 -> 1188000 | J7: =H7*E7 -> 462000 | K7: =INDEX([1]LLMs!$C$2:$C$9,MATCH(B7,[1]LLMs!$A$2:$A$9,0)) -> 1 | L7: =INDEX([1]LLMs!$D$2:$D$9,MATCH(B7,[1]LLMs!$A$2:$A$9,0)) -> 3 | M7: =I7/1000000*K7 -> 1.188 | N7: =J7/1000000*L7 -> 1.386 | O7: =M7+N7 -> 2.574 | P7: =O7*12 -> 30.888
A9: TOTAL | E9: =SUM(E2:E8) -> 8074 | F9: =SUM(F2:F8) -> 96888 | I9: =SUM(I2:I8) -> 13354000 | J9: =SUM(J2:J8) -> 5293200 | M9: =SUM(M2:M8) -> 13.354 | N9: =SUM(N2:N8) -> 15.8796 | O9: =SUM(O2:O8) -> 29.2336 | P9: =SUM(P2:P8) -> 350.8032
A11: RESUMEN FINANCIERO
A12: Número de agentes | B12: =COUNTA(A2:A8) -> 6
A13: Coste IA mensual total | B13: =O9 -> 29.2336
A14: Coste IA anual total | B14: =P9 -> 350.8032
A15: Margen de seguridad (%) | B15: =[1]Configuración!B5/100 -> 0.1
A16: Coste anual + margen de seguridad | B16: =P9*(1+[1]Configuración!B5/100) -> 385.88352
A17: IVA (%) | B17: =[1]Configuración!B4/100 -> 0.21
A18: Coste anual + margen + IVA | B18: =P9*(1+[1]Configuración!B5/100)*(1+[1]Configuración!B4/100) -> 466.91906

Sheet Agentes
A1: Agente | B1: LLM | C1: Consultas/día | D1: Días/mes | E1: Consultas/mes | F1: Consultas/año | G1: Input tok/consulta | H1: Output tok/consulta | I1: Input tok/mes | J1: Output tok/mes | K1: €/Entrada | L1: €/Salida | M1: Coste Entrada | N1: Coste Salida | O1: TOTAL Mes | P1: TOTAL Año
A2: Garum (Gestor Correos) | B2: Grok 4 | C2: 55 | D2: =Configuración!$B$2 -> 30 | E2: =C2*D2 -> 1650 | F2: =E2*12 -> 19800 | G2: 1200 | H2: 500 | I2: =G2*E2 -> 1980000 | J2: =H2*E2 -> 825000 | K2: =INDEX(LLMs!$C$2:$C$9,MATCH(B2,LLMs!$A$2:$A$9,0)) -> 0.59 | L2: =INDEX(LLMs!$D$2:$D$9,MATCH(B2,LLMs!$A$2:$A$9,0)) -> 0.79 | M2: =I2/1000000*K2 -> 1.1682 | N2: =J2/1000000*L2 -> 0.65175 | O2: =M2+N2 -> 1.81995 | P2: =O2*12 -> 21.8394
A3: Hermes (Telegram) | B3: Grok 4 | C3: 20 | D3: =Configuración!$B$2 -> 30 | E3: =C3*D3 -> 600 | F3: =E3*12 -> 7200 | G3: 900 | H3: 450 | I3: =G3*E3 -> 540000 | J3: =H3*E3 -> 270000 | K3: =INDEX(LLMs!$C$2:$C$9,MATCH(B3,LLMs!$A$2:$A$9,0)) -> 0.59 | L3: =INDEX(LLMs!$D$2:$D$9,MATCH(B3,LLMs!$A$2:$A$9,0)) -> 0.79 | M3: =I3/1000000*K3 -> 0.3186 | N3: =J3/1000000*L3 -> 0.2133 | O3: =M3+N3 -> 0.5319 | P3: =O3*12 -> 6.3828
A4: Lumen (consultas) | B4: Grok 4 | C4: 50 | D4: =Configuración!$B$2 -> 30 | E4: =C4*D4 -> 1500 | F4: =E4*12 -> 18000 | G4: 2500 | H4: 900 | I4: =G4*E4 -> 3750000 | J4: =H4*E4 -> 1350000 | K4: =INDEX(LLMs!$C$2:$C$9,MATCH(B4,LLMs!$A$2:$A$9,0)) -> 0.59 | L4: =INDEX(LLMs!$D$2:$D$9,MATCH(B4,LLMs!$A$2:$A$9,0)) -> 0.79 | M4: =I4/1000000*K4 -> 2.2125 | N4: =J4/1000000*L4 -> 1.0665 | O4: =M4+N4 -> 3.279 | P4: =O4*12 -> 39.348
A5: Operis (autorellenado) | B5: Grok 4 | C5: 10 | D5: =Configuración!$B$2 -> 30 | E5: =C5*D5 -> 300 | F5: =E5*12 -> 3600 | G5: 1100 | H5: 400 | I5: =G5*E5 -> 330000 | J5: =H5*E5 -> 120000 | K5: =INDEX(LLMs!$C$2:$C$9,MATCH(B5,LLMs!$A$2:$A$9,0)) -> 0.59 | L5: =INDEX(LLMs!$D$2:$D$9,MATCH(B5,LLMs!$A$2:$A$9,0)) -> 0.79 | M5: =I5/1000000*K5 -> 0.1947 | N5: =J5/1000000*L5 -> 0.0948 | O5: =M5+N5 -> 0.2895 | P5: =O5*12 -> 3.474
A6: Vigil (concursos) | B6: Grok 4 | C6: 2 | D6: =Configuración!$B$2 -> 30 | E6: =C6*D6 -> 60 | F6: =E6*12 -> 720 | G6: 1000 | H6: 300 | I6: =G6*E6 -> 60000 | J6: =H6*E6 -> 18000 | K6: =INDEX(LLMs!$C$2:$C$9,MATCH(B6,LLMs!$A$2:$A$9,0)) -> 0.59 | L6: =INDEX(LLMs!$D$2:$D$9,MATCH(B6,LLMs!$A$2:$A$9,0)) -> 0.79 | M6: =I6/1000000*K6 -> 0.0354 | N6: =J6/1000000*L6 -> 0.01422 | O6: =M6+N6 -> 0.04962 | P6: =O6*12 -> 0.59544
A7: Jano (viajes) | B7: Grok 4 | C7: 15 | D7: =Configuración!$B$2 -> 30 | E7: =C7*D7 -> 450 | F7: =E7*12 -> 5400 | G7: 1800 | H7: 700 | I7: =G7*E7 -> 810000 | J7: =H7*E7 -> 315000 | K7: =INDEX(LLMs!$C$2:$C$9,MATCH(B7,LLMs!$A$2:$A$9,0)) -> 0.59 | L7: =INDEX(LLMs!$D$2:$D$9,MATCH(B7,LLMs!$A$2:$A$9,0)) -> 0.79 | M7: =I7/1000000*K7 -> 0.4779 | N7: =J7/1000000*L7 -> 0.24885 | O7: =M7+N7 -> 0.72675 | P7: =O7*12 -> 8.721
A9: TOTAL | E9: =SUM(E2:E8) -> 4560 | F9: =SUM(F2:F8) -> 54720 | I9: =SUM(I2:I8) -> 7470000 | J9: =SUM(J2:J8) -> 2898000 | M9: =SUM(M2:M8) -> 4.4073 | N9: =SUM(N2:N8) -> 2.28942 | O9: =SUM(O2:O8) -> 6.69672 | P9: =SUM(P2:P8) -> 80.36064
A11: RESUMEN FINANCIERO
A12: Número de agentes | B12: =COUNTA(A2:A8) -> 6
A13: Coste IA mensual total | B13: =O9 -> 6.69672
A14: Coste IA anual total | B14: =P9 -> 80.36064
A15: Margen de seguridad (%) | B15: =Configuración!B5/100 -> 0.15
A16: Coste anual + margen de seguridad | B16: =P9*(1+Configuración!B5/100) -> 92.414736
A17: IVA (%) | B17: =Configuración!B4/100 -> 0.21
A18: Coste anual + margen + IVA | B18: =P9*(1+Configuración!B5/100)*(1+Configuración!B4/100) -> 111.82183
B22: alojamiento | C22: 14

Sheet Histórico
A1: Mes | B1: Garum | C1: Hermes | D1: Lumen | E1: Operis | F1: Vigil | G1: Jano | H1: Clasificador | I1: TOTAL | K1: Filtro de agente: | L1: Todos
A2: Ene | B2: 22 | C2: 27 | D2: 32 | E2: 37 | F2: 42 | G2: 47 | H2: 52 | I2: =SUM(B2:H2) -> 259
A3: Feb | B3: 23 | C3: 28 | D3: 33 | E3: 38 | F3: 43 | G3: 48 | H3: 53 | I3: =SUM(B3:H3) -> 266 | K3: TABLA AUXILIAR (alimenta el gráfico según el filtro)
A4: Mar | B4: 24 | C4: 29 | D4: 34 | E4: 39 | F4: 44 | G4: 49 | H4: 54 | I4: =SUM(B4:H4) -> 273 | K4: =A1 -> Mes | L4: =B1 -> Garum | M4: =C1 -> Hermes | N4: =D1 -> Lumen | O4: =E1 -> Operis | P4: =F1 -> Vigil | Q4: =G1 -> Jano | R4: =H1 -> Clasificador | S4: =I1 -> TOTAL
A5: Abr | B5: 25 | C5: 30 | D5: 35 | E5: 40 | F5: 45 | G5: 50 | H5: 55 | I5: =SUM(B5:H5) -> 280 | K5: =A2 -> Ene | L5: =IF(OR($L$1="Todos",$L$1=L$4),B2,NA()) -> 22 | M5: =IF(OR($L$1="Todos",$L$1=M$4),C2,NA()) -> 27 | N5: =IF(OR($L$1="Todos",$L$1=N$4),D2,NA()) -> 32 | O5: =IF(OR($L$1="Todos",$L$1=O$4),E2,NA()) -> 37 | P5: =IF(OR($L$1="Todos",$L$1=P$4),F2,NA()) -> 42 | Q5: =IF(OR($L$1="Todos",$L$1=Q$4),G2,NA()) -> 47 | R5: =IF(OR($L$1="Todos",$L$1=R$4),H2,NA()) -> 52 | S5: =IF(OR($L$1="Todos",$L$1=S$4),I2,NA()) -> 259
A6: May | B6: 26 | C6: 31 | D6: 36 | E6: 41 | F6: 46 | G6: 51 | H6: 56 | I6: =SUM(B6:H6) -> 287 | K6: =A3 -> Feb | L6: =IF(OR($L$1="Todos",$L$1=L$4),B3,NA()) -> 23 | M6: =IF(OR($L$1="Todos",$L$1=M$4),C3,NA()) -> 28 | N6: =IF(OR($L$1="Todos",$L$1=N$4),D3,NA()) -> 33 | O6: =IF(OR($L$1="Todos",$L$1=O$4),E3,NA()) -> 38 | P6: =IF(OR($L$1="Todos",$L$1=P$4),F3,NA()) -> 43 | Q6: =IF(OR($L$1="Todos",$L$1=Q$4),G3,NA()) -> 48 | R6: =IF(OR($L$1="Todos",$L$1=R$4),H3,NA()) -> 53 | S6: =IF(OR($L$1="Todos",$L$1=S$4),I3,NA()) -> 266
A7: Jun | B7: 27 | C7: 32 | D7: 37 | E7: 42 | F7: 47 | G7: 52 | H7: 57 | I7: =SUM(B7:H7) -> 294 | K7: =A4 -> Mar | L7: =IF(OR($L$1="Todos",$L$1=L$4),B4,NA()) -> 24 | M7: =IF(OR($L$1="Todos",$L$1=M$4),C4,NA()) -> 29 | N7: =IF(OR($L$1="Todos",$L$1=N$4),D4,NA()) -> 34 | O7: =IF(OR($L$1="Todos",$L$1=O$4),E4,NA()) -> 39 | P7: =IF(OR($L$1="Todos",$L$1=P$4),F4,NA()) -> 44 | Q7: =IF(OR($L$1="Todos",$L$1=Q$4),G4,NA()) -> 49 | R7: =IF(OR($L$1="Todos",$L$1=R$4),H4,NA()) -> 54 | S7: =IF(OR($L$1="Todos",$L$1=S$4),I4,NA()) -> 273
A8: Jul | B8: 28 | C8: 33 | D8: 38 | E8: 43 | F8: 48 | G8: 53 | H8: 58 | I8: =SUM(B8:H8) -> 301 | K8: =A5 -> Abr | L8: =IF(OR($L$1="Todos",$L$1=L$4),B5,NA()) -> 25 | M8: =IF(OR($L$1="Todos",$L$1=M$4),C5,NA()) -> 30 | N8: =IF(OR($L$1="Todos",$L$1=N$4),D5,NA()) -> 35 | O8: =IF(OR($L$1="Todos",$L$1=O$4),E5,NA()) -> 40 | P8: =IF(OR($L$1="Todos",$L$1=P$4),F5,NA()) -> 45 | Q8: =IF(OR($L$1="Todos",$L$1=Q$4),G5,NA()) -> 50 | R8: =IF(OR($L$1="Todos",$L$1=R$4),H5,NA()) -> 55 | S8: =IF(OR($L$1="Todos",$L$1=S$4),I5,NA()) -> 280
A9: Ago | B9: 29 | C9: 34 | D9: 39 | E9: 44 | F9: 49 | G9: 54 | H9: 59 | I9: =SUM(B9:H9) -> 308 | K9: =A6 -> May | L9: =IF(OR($L$1="Todos",$L$1=L$4),B6,NA()) -> 26 | M9: =IF(OR($L$1="Todos",$L$1=M$4),C6,NA()) -> 31 | N9: =IF(OR($L$1="Todos",$L$1=N$4),D6,NA()) -> 36 | O9: =IF(OR($L$1="Todos",$L$1=O$4),E6,NA()) -> 41 | P9: =IF(OR($L$1="Todos",$L$1=P$4),F6,NA()) -> 46 | Q9: =IF(OR($L$1="Todos",$L$1=Q$4),G6,NA()) -> 51 | R9: =IF(OR($L$1="Todos",$L$1=R$4),H6,NA()) -> 56 | S9: =IF(OR($L$1="Todos",$L$1=S$4),I6,NA()) -> 287
A10: Sep | B10: 30 | C10: 35 | D10: 40 | E10: 45 | F10: 50 | G10: 55 | H10: 60 | I10: =SUM(B10:H10) -> 315 | K10: =A7 -> Jun | L10: =IF(OR($L$1="Todos",$L$1=L$4),B7,NA()) -> 27 | M10: =IF(OR($L$1="Todos",$L$1=M$4),C7,NA()) -> 32 | N10: =IF(OR($L$1="Todos",$L$1=N$4),D7,NA()) -> 37 | O10: =IF(OR($L$1="Todos",$L$1=O$4),E7,NA()) -> 42 | P10: =IF(OR($L$1="Todos",$L$1=P$4),F7,NA()) -> 47 | Q10: =IF(OR($L$1="Todos",$L$1=Q$4),G7,NA()) -> 52 | R10: =IF(OR($L$1="Todos",$L$1=R$4),H7,NA()) -> 57 | S10: =IF(OR($L$1="Todos",$L$1=S$4),I7,NA()) -> 294
A11: Oct | B11: 31 | C11: 36 | D11: 41 | E11: 46 | F11: 51 | G11: 56 | H11: 61 | I11: =SUM(B11:H11) -> 322 | K11: =A8 -> Jul | L11: =IF(OR($L$1="Todos",$L$1=L$4),B8,NA()) -> 28 | M11: =IF(OR($L$1="Todos",$L$1=M$4),C8,NA()) -> 33 | N11: =IF(OR($L$1="Todos",$L$1=N$4),D8,NA()) -> 38 | O11: =IF(OR($L$1="Todos",$L$1=O$4),E8,NA()) -> 43 | P11: =IF(OR($L$1="Todos",$L$1=P$4),F8,NA()) -> 48 | Q11: =IF(OR($L$1="Todos",$L$1=Q$4),G8,NA()) -> 53 | R11: =IF(OR($L$1="Todos",$L$1=R$4),H8,NA()) -> 58 | S11: =IF(OR($L$1="Todos",$L$1=S$4),I8,NA()) -> 301
A12: Nov | B12: 32 | C12: 37 | D12: 42 | E12: 47 | F12: 52 | G12: 57 | H12: 62 | I12: =SUM(B12:H12) -> 329 | K12: =A9 -> Ago | L12: =IF(OR($L$1="Todos",$L$1=L$4),B9,NA()) -> 29 | M12: =IF(OR($L$1="Todos",$L$1=M$4),C9,NA()) -> 34 | N12: =IF(OR($L$1="Todos",$L$1=N$4),D9,NA()) -> 39 | O12: =IF(OR($L$1="Todos",$L$1=O$4),E9,NA()) -> 44 | P12: =IF(OR($L$1="Todos",$L$1=P$4),F9,NA()) -> 49 | Q12: =IF(OR($L$1="Todos",$L$1=Q$4),G9,NA()) -> 54 | R12: =IF(OR($L$1="Todos",$L$1=R$4),H9,NA()) -> 59 | S12: =IF(OR($L$1="Todos",$L$1=S$4),I9,NA()) -> 308
A13: Dic | B13: 33 | C13: 38 | D13: 43 | E13: 48 | F13: 53 | G13: 58 | H13: 63 | I13: =SUM(B13:H13) -> 336 | K13: =A10 -> Sep | L13: =IF(OR($L$1="Todos",$L$1=L$4),B10,NA()) -> 30 | M13: =IF(OR($L$1="Todos",$L$1=M$4),C10,NA()) -> 35 | N13: =IF(OR($L$1="Todos",$L$1=N$4),D10,NA()) -> 40 | O13: =IF(OR($L$1="Todos",$L$1=O$4),E10,NA()) -> 45 | P13: =IF(OR($L$1="Todos",$L$1=P$4),F10,NA()) -> 50 | Q13: =IF(OR($L$1="Todos",$L$1=Q$4),G10,NA()) -> 55 | R13: =IF(OR($L$1="Todos",$L$1=R$4),H10,NA()) -> 60 | S13: =IF(OR($L$1="Todos",$L$1=S$4),I10,NA()) -> 315
K14: =A11 -> Oct | L14: =IF(OR($L$1="Todos",$L$1=L$4),B11,NA()) -> 31 | M14: =IF(OR($L$1="Todos",$L$1=M$4),C11,NA()) -> 36 | N14: =IF(OR($L$1="Todos",$L$1=N$4),D11,NA()) -> 41 | O14: =IF(OR($L$1="Todos",$L$1=O$4),E11,NA()) -> 46 | P14: =IF(OR($L$1="Todos",$L$1=P$4),F11,NA()) -> 51 | Q14: =IF(OR($L$1="Todos",$L$1=Q$4),G11,NA()) -> 56 | R14: =IF(OR($L$1="Todos",$L$1=R$4),H11,NA()) -> 61 | S14: =IF(OR($L$1="Todos",$L$1=S$4),I11,NA()) -> 322
K15: =A12 -> Nov | L15: =IF(OR($L$1="Todos",$L$1=L$4),B12,NA()) -> 32 | M15: =IF(OR($L$1="Todos",$L$1=M$4),C12,NA()) -> 37 | N15: =IF(OR($L$1="Todos",$L$1=N$4),D12,NA()) -> 42 | O15: =IF(OR($L$1="Todos",$L$1=O$4),E12,NA()) -> 47 | P15: =IF(OR($L$1="Todos",$L$1=P$4),F12,NA()) -> 52 | Q15: =IF(OR($L$1="Todos",$L$1=Q$4),G12,NA()) -> 57 | R15: =IF(OR($L$1="Todos",$L$1=R$4),H12,NA()) -> 62 | S15: =IF(OR($L$1="Todos",$L$1=S$4),I12,NA()) -> 329
K16: =A13 -> Dic | L16: =IF(OR($L$1="Todos",$L$1=L$4),B13,NA()) -> 33 | M16: =IF(OR($L$1="Todos",$L$1=M$4),C13,NA()) -> 38 | N16: =IF(OR($L$1="Todos",$L$1=N$4),D13,NA()) -> 43 | O16: =IF(OR($L$1="Todos",$L$1=O$4),E13,NA()) -> 48 | P16: =IF(OR($L$1="Todos",$L$1=P$4),F13,NA()) -> 53 | Q16: =IF(OR($L$1="Todos",$L$1=Q$4),G13,NA()) -> 58 | R16: =IF(OR($L$1="Todos",$L$1=R$4),H13,NA()) -> 63 | S16: =IF(OR($L$1="Todos",$L$1=S$4),I13,NA()) -> 336

Sheet Comparador Agentes
A1: Agente | B1: Coste mensual | C1: Coste anual | D1: Coste por consulta | E1: Coste por millón tokens | G1: Aux mensual | H1: Aux anual | I1: Aux consulta | J1: Aux tokens
A2: =Agentes!A2 -> Garum (Gestor Correos) | B2: =Agentes!O2 -> 1.81995 | C2: =Agentes!P2 -> 21.8394 | D2: =Agentes!O2/Agentes!E2 -> 0.001103 | E2: =Agentes!O2/((Agentes!I2+Agentes!J2)/1000000) -> 0.64882353 | G2: =B2+(ROW()-2)*0.0000001 -> 1.81995 | H2: =C2+(ROW()-2)*0.0000001 -> 21.8394 | I2: =D2+(ROW()-2)*0.0000001 -> 0.001103 | J2: =E2+(ROW()-2)*0.0000001 -> 0.64882353
A3: =Agentes!A3 -> Hermes (Telegram) | B3: =Agentes!O3 -> 0.5319 | C3: =Agentes!P3 -> 6.3828 | D3: =Agentes!O3/Agentes!E3 -> 0.0008865 | E3: =Agentes!O3/((Agentes!I3+Agentes!J3)/1000000) -> 0.65666667 | G3: =B3+(ROW()-2)*0.0000001 -> 0.5319001 | H3: =C3+(ROW()-2)*0.0000001 -> 6.3828001 | I3: =D3+(ROW()-2)*0.0000001 -> 0.0008866 | J3: =E3+(ROW()-2)*0.0000001 -> 0.65666677
A4: =Agentes!A4 -> Lumen (consultas) | B4: =Agentes!O4 -> 3.279 | C4: =Agentes!P4 -> 39.348 | D4: =Agentes!O4/Agentes!E4 -> 0.002186 | E4: =Agentes!O4/((Agentes!I4+Agentes!J4)/1000000) -> 0.64294118 | G4: =B4+(ROW()-2)*0.0000001 -> 3.2790002 | H4: =C4+(ROW()-2)*0.0000001 -> 39.348 | I4: =D4+(ROW()-2)*0.0000001 -> 0.0021862 | J4: =E4+(ROW()-2)*0.0000001 -> 0.64294138
A5: =Agentes!A5 -> Operis (autorellenado) | B5: =Agentes!O5 -> 0.2895 | C5: =Agentes!P5 -> 3.474 | D5: =Agentes!O5/Agentes!E5 -> 0.000965 | E5: =Agentes!O5/((Agentes!I5+Agentes!J5)/1000000) -> 0.64333333 | G5: =B5+(ROW()-2)*0.0000001 -> 0.2895003 | H5: =C5+(ROW()-2)*0.0000001 -> 3.4740003 | I5: =D5+(ROW()-2)*0.0000001 -> 0.0009653 | J5: =E5+(ROW()-2)*0.0000001 -> 0.64333363
A6: =Agentes!A6 -> Vigil (concursos) | B6: =Agentes!O6 -> 0.04962 | C6: =Agentes!P6 -> 0.59544 | D6: =Agentes!O6/Agentes!E6 -> 0.000827 | E6: =Agentes!O6/((Agentes!I6+Agentes!J6)/1000000) -> 0.63615385 | G6: =B6+(ROW()-2)*0.0000001 -> 0.0496204 | H6: =C6+(ROW()-2)*0.0000001 -> 0.5954404 | I6: =D6+(ROW()-2)*0.0000001 -> 0.0008274 | J6: =E6+(ROW()-2)*0.0000001 -> 0.63615425
A7: =Agentes!A7 -> Jano (viajes) | B7: =Agentes!O7 -> 0.72675 | C7: =Agentes!P7 -> 8.721 | D7: =Agentes!O7/Agentes!E7 -> 0.001615 | E7: =Agentes!O7/((Agentes!I7+Agentes!J7)/1000000) -> 0.646 | G7: =B7+(ROW()-2)*0.0000001 -> 0.7267505 | H7: =C7+(ROW()-2)*0.0000001 -> 8.7210005 | I7: =D7+(ROW()-2)*0.0000001 -> 0.0016155 | J7: =E7+(ROW()-2)*0.0000001 -> 0.6460005
G8: =B8+(ROW()-2)*0.0000001 -> 6e-07 | H8: =C8+(ROW()-2)*0.0000001 -> 6e-07 | I8: =D8+(ROW()-2)*0.0000001 -> 6e-07 | J8: =E8+(ROW()-2)*0.0000001 -> 6e-07
A10: RANKING POR COSTE MENSUAL
A11: Posición | B11: Agente | C11: Coste mensual
A12: 1 | B12: =INDEX($A$2:$A$8,MATCH(LARGE($G$2:$G$8,1),$G$2:$G$8,0)) -> Lumen (consultas) | C12: =LARGE($G$2:$G$8,1) -> 3.2790002
A13: 2 | B13: =INDEX($A$2:$A$8,MATCH(LARGE($G$2:$G$8,2),$G$2:$G$8,0)) -> Garum (Gestor Correos) | C13: =LARGE($G$2:$G$8,2) -> 1.81995
A14: 3 | B14: =INDEX($A$2:$A$8,MATCH(LARGE($G$2:$G$8,3),$G$2:$G$8,0)) -> Jano (viajes) | C14: =LARGE($G$2:$G$8,3) -> 0.7267505
A15: 4 | B15: =INDEX($A$2:$A$8,MATCH(LARGE($G$2:$G$8,4),$G$2:$G$8,0)) -> Hermes (Telegram) | C15: =LARGE($G$2:$G$8,4) -> 0.5319001
A16: 5 | B16: =INDEX($A$2:$A$8,MATCH(LARGE($G$2:$G$8,5),$G$2:$G$8,0)) -> Operis (autorellenado) | C16: =LARGE($G$2:$G$8,5) -> 0.2895003
A17: 6 | B17: =INDEX($A$2:$A$8,MATCH(LARGE($G$2:$G$8,6),$G$2:$G$8,0)) -> Vigil (concursos) | C17: =LARGE($G$2:$G$8,6) -> 0.0496204
A18: 7 | B18: =INDEX($A$2:$A$8,MATCH(LARGE($G$2:$G$8,7),$G$2:$G$8,0)) -> 0 | C18: =LARGE($G$2:$G$8,7) -> 6e-07
A20: RANKING POR COSTE ANUAL
A21: Posición | B21: Agente | C21: Coste anual
A22: 1 | B22: =INDEX($A$2:$A$8,MATCH(LARGE($H$2:$H$8,1),$H$2:$H$8,0)) -> Lumen (consultas) | C22: =LARGE($H$2:$H$8,1) -> 39.348
A23: 2 | B23: =INDEX($A$2:$A$8,MATCH(LARGE($H$2:$H$8,2),$H$2:$H$8,0)) -> Garum (Gestor Correos) | C23: =LARGE($H$2:$H$8,2) -> 21.8394
A24: 3 | B24: =INDEX($A$2:$A$8,MATCH(LARGE($H$2:$H$8,3),$H$2:$H$8,0)) -> Jano (viajes) | C24: =LARGE($H$2:$H$8,3) -> 8.7210005
A25: 4 | B25: =INDEX($A$2:$A$8,MATCH(LARGE($H$2:$H$8,4),$H$2:$H$8,0)) -> Hermes (Telegram) | C25: =LARGE($H$2:$H$8,4) -> 6.3828001
A26: 5 | B26: =INDEX($A$2:$A$8,MATCH(LARGE($H$2:$H$8,5),$H$2:$H$8,0)) -> Operis (autorellenado) | C26: =LARGE($H$2:$H$8,5) -> 3.4740003
A27: 6 | B27: =INDEX($A$2:$A$8,MATCH(LARGE($H$2:$H$8,6),$H$2:$H$8,0)) -> Vigil (concursos) | C27: =LARGE($H$2:$H$8,6) -> 0.5954404
A28: 7 | B28: =INDEX($A$2:$A$8,MATCH(LARGE($H$2:$H$8,7),$H$2:$H$8,0)) -> 0 | C28: =LARGE($H$2:$H$8,7) -> 6e-07
A30: RANKING POR COSTE POR CONSULTA
A31: Posición | B31: Agente | C31: Coste por consulta
A32: 1 | B32: =INDEX($A$2:$A$8,MATCH(LARGE($I$2:$I$8,1),$I$2:$I$8,0)) -> Lumen (consultas) | C32: =LARGE($I$2:$I$8,1) -> 0.0021862
A33: 2 | B33: =INDEX($A$2:$A$8,MATCH(LARGE($I$2:$I$8,2),$I$2:$I$8,0)) -> Jano (viajes) | C33: =LARGE($I$2:$I$8,2) -> 0.0016155
A34: 3 | B34: =INDEX($A$2:$A$8,MATCH(LARGE($I$2:$I$8,3),$I$2:$I$8,0)) -> Garum (Gestor Correos) | C34: =LARGE($I$2:$I$8,3) -> 0.001103
A35: 4 | B35: =INDEX($A$2:$A$8,MATCH(LARGE($I$2:$I$8,4),$I$2:$I$8,0)) -> Operis (autorellenado) | C35: =LARGE($I$2:$I$8,4) -> 0.0009653
A36: 5 | B36: =INDEX($A$2:$A$8,MATCH(LARGE($I$2:$I$8,5),$I$2:$I$8,0)) -> Hermes (Telegram) | C36: =LARGE($I$2:$I$8,5) -> 0.0008866
A37: 6 | B37: =INDEX($A$2:$A$8,MATCH(LARGE($I$2:$I$8,6),$I$2:$I$8,0)) -> Vigil (concursos) | C37: =LARGE($I$2:$I$8,6) -> 0.0008274
A38: 7 | B38: =INDEX($A$2:$A$8,MATCH(LARGE($I$2:$I$8,7),$I$2:$I$8,0)) -> 0 | C38: =LARGE($I$2:$I$8,7) -> 6e-07
A40: RANKING POR COSTE POR MILLÓN DE TOKENS
A41: Posición | B41: Agente | C41: Coste por millón tokens
A42: 1 | B42: =INDEX($A$2:$A$8,MATCH(LARGE($J$2:$J$8,1),$J$2:$J$8,0)) -> Hermes (Telegram) | C42: =LARGE($J$2:$J$8,1) -> 0.65666677
A43: 2 | B43: =INDEX($A$2:$A$8,MATCH(LARGE($J$2:$J$8,2),$J$2:$J$8,0)) -> Garum (Gestor Correos) | C43: =LARGE($J$2:$J$8,2) -> 0.64882353
A44: 3 | B44: =INDEX($A$2:$A$8,MATCH(LARGE($J$2:$J$8,3),$J$2:$J$8,0)) -> Jano (viajes) | C44: =LARGE($J$2:$J$8,3) -> 0.6460005
...

Sheet Dashboard
A1: DASHBOARD EJECUTIVO — ESTUDIO ECONÓMICO AGENTES IA
A4: COSTE TOTAL MENSUAL | C4: COSTE TOTAL ANUAL | E4: NÚMERO DE AGENTES | G4: COSTE MEDIO / AGENTE
A5: =Agentes!O9+#REF! -> #REF! | C5: =Agentes!P9+#REF! -> #REF! | E5: =COUNTA(Agentes!A2:A8) -> 6 | G5: =Agentes!O9/COUNTA(Agentes!A2:A8) -> 1.11612
A7: AGENTE MÁS CARO | C7: AGENTE MÁS ECONÓMICO | E7: COSTE IA (MENSUAL) | G7: COSTE INFRAESTRUCTURA (MENSUAL)
A8: =INDEX(Agentes!A2:A8,MATCH(MAX(Agentes!O2:O8),Agentes!O2:O8,0)) -> Lumen (consultas) | C8: =INDEX(Agentes!A2:A8,MATCH(MIN(Agentes!O2:O8),Agentes!O2:O8,0)) -> Vigil (concursos) | E8: =Agentes!O9 -> 6.69672 | G8: =#REF! -> #REF!
A10: DESPLIEGUE INICIAL | C10: DESPLIEGUE ANUAL | E10: COSTE TOTAL PRIMER AÑO | G10: COSTE ANUAL + MARGEN + IVA
A11: =#REF! -> #REF! | C11: =#REF! -> #REF! | E11: =Agentes!P9+#REF!+#REF! -> #REF! | G11: =Agentes!B18+#REF! -> #REF!
A46: TABLA DE APOYO — Comparativa IA vs Infraestructura (fuente del Gráfico 5)
A47: Concepto | B47: Coste IA | C47: Coste Infraestructura
A48: Mensual | B48: =Agentes!O9 -> 6.69672 | C48: =#REF! -> #REF!
A49: Anual | B49: =Agentes!P9 -> 80.36064 | C49: =#REF! -> #REF!

Sheet ROI_Ahorro
A1: Agente | B1: Tiempo manual (min) | C1: Tiempo IA (min) | D1: Ahorro por tarea (min) | E1: Consultas/mes | F1: Horas ahorradas/mes | G1: Horas ahorradas/año | H1: Coste empleado €/h | I1: Ahorro económico mensual (€) | J1: Ahorro económico anual (€)
A2: Garum (Correo) | B2: 8 | C2: 1 | D2: =B2-C2 -> 7 | E2: 1650 | F2: =(D2*E2)/60 -> 192.5 | G2: =F2*12 -> 2310 | H2: 12 | I2: =F2*H2 -> 2310 | J2: =G2*H2 -> 27720
A3: Hermes (Telegram) | B3: 5 | C3: 0.5 | D3: =B3-C3 -> 4.5 | E3: 600 | F3: =(D3*E3)/60 -> 45 | G3: =F3*12 -> 540 | H3: 20 | I3: =F3*H3 -> 900 | J3: =G3*H3 -> 10800
A4: Lumen (Consultas) | B4: 6 | C4: 0.33 | D4: =B4-C4 -> 5.67 | E4: 1500 | F4: =(D4*E4)/60 -> 141.75 | G4: =F4*12 -> 1701 | H4: 20 | I4: =F4*H4 -> 2835 | J4: =G4*H4 -> 34020
A5: Operis (Autorrellenado) | B5: 15 | C5: 2 | D5: =B5-C5 -> 13 | E5: 300 | F5: =(D5*E5)/60 -> 65 | G5: =F5*12 -> 780 | H5: 20 | I5: =F5*H5 -> 1300 | J5: =G5*H5 -> 15600
A6: Vigil (Concursos) | B6: 60 | C6: 5 | D6: =B6-C6 -> 55 | E6: 60 | F6: =(D6*E6)/60 -> 55 | G6: =F6*12 -> 660 | H6: 20 | I6: =F6*H6 -> 1100 | J6: =G6*H6 -> 13200
A7: Jano (Viajes) | B7: 25 | C7: 5 | D7: =B7-C7 -> 20 | E7: 450 | F7: =(D7*E7)/60 -> 150 | G7: =F7*12 -> 1800 | H7: 20 | I7: =F7*H7 -> 3000 | J7: =G7*H7 -> 36000
E9: TOTALES | F9: =SUM(F2:F7) -> 649.25 | G9: =SUM(G2:G7) -> 7791 | I9: =SUM(I2:I7) -> 11445 | J9: =SUM(J2:J7) -> 137340
A12: KPIs
A13: Empleados equivalentes (160 h/mes) | B13: =F9/160 -> 4.0578125
A14: Coste anual de 1 empleado (€) | B14: 30000
A15: Valor anual equivalente (€) | B15: =B13*B14 -> 121734.38
A16: ROI estimado (€) | B16: =MAX(B15-J9,0) -> 0
